django.request WARNING 2024-06-13 01:45:46,455 log 7818 139640415692352 Not Found: /customers/8e05b134-0b51-46e4-ac9d-2e725f265a9b/orders/styles.css.map
customers.views WARNING 2024-06-13 01:45:53,981 views 7818 139640407299648 <WSGIRequest: GET '/customers/8e05b134-0b51-46e4-ac9d-2e725f265a9b/orders/8/invoice_create/'>
customers.views WARNING 2024-06-13 01:45:53,981 views 7818 139640407299648 8e05b134-0b51-46e4-ac9d-2e725f265a9b
customers.views WARNING 2024-06-13 01:45:53,982 views 7818 139640407299648 8
django.request ERROR 2024-06-13 01:45:54,140 log 7818 139640407299648 Internal Server Error: /customers/8e05b134-0b51-46e4-ac9d-2e725f265a9b/orders/8/invoice_create/
Traceback (most recent call last):
  File "/workspace/.pip-modules/lib/python3.12/site-packages/django/core/handlers/exception.py", line 55, in inner
    response = get_response(request)
               ^^^^^^^^^^^^^^^^^^^^^
  File "/workspace/.pip-modules/lib/python3.12/site-packages/django/core/handlers/base.py", line 204, in _get_response
    self.check_response(response, callback)
  File "/workspace/.pip-modules/lib/python3.12/site-packages/django/core/handlers/base.py", line 332, in check_response
    raise ValueError(
ValueError: The view customers.views.invoice_create didn't return an HttpResponse object. It returned None instead.
django.request WARNING 2024-06-13 01:45:54,333 log 7818 139639922882112 Not Found: /favicon.ico
django.request WARNING 2024-06-13 01:45:54,398 log 7818 139639914489408 Not Found: /customers/8e05b134-0b51-46e4-ac9d-2e725f265a9b/orders/8/invoice_create/styles.css.map
django.utils.autoreload INFO 2024-06-13 01:47:17,695 autoreload 7818 139640743861120 /workspace/django-renterprise/customers/views.py changed, reloading.
django.utils.autoreload INFO 2024-06-13 01:47:18,316 autoreload 7944 139890667793280 Watching for file changes with StatReloader
django.request WARNING 2024-06-13 01:47:24,276 log 7944 139890602612288 Not Found: /customers/8e05b134-0b51-46e4-ac9d-2e725f265a9b/orders/styles.css.map
urllib3.connectionpool DEBUG 2024-06-13 01:47:24,812 connectionpool 7944 139890594203200 Starting new HTTPS connection (1): res.cloudinary.com:443
urllib3.connectionpool DEBUG 2024-06-13 01:47:24,877 connectionpool 7944 139890594203200 https://res.cloudinary.com:443 "GET /dddubflsq/raw/upload/v1/static/staticfiles.json HTTP/1.1" 200 None
django.request WARNING 2024-06-13 01:47:25,785 log 7944 139890347984448 Not Found: /customers/8e05b134-0b51-46e4-ac9d-2e725f265a9b/orders/styles.css.map
django.request WARNING 2024-06-13 01:47:27,415 log 7944 139889752397376 Not Found: /customers/8e05b134-0b51-46e4-ac9d-2e725f265a9b/orders/styles.css.map
customers.views WARNING 2024-06-13 01:47:31,398 views 7944 139889744004672 <WSGIRequest: GET '/customers/8e05b134-0b51-46e4-ac9d-2e725f265a9b/orders/8/invoice_create/'>
django.request ERROR 2024-06-13 01:47:31,553 log 7944 139889744004672 Internal Server Error: /customers/8e05b134-0b51-46e4-ac9d-2e725f265a9b/orders/8/invoice_create/
Traceback (most recent call last):
  File "/workspace/.pip-modules/lib/python3.12/site-packages/django/core/handlers/exception.py", line 55, in inner
    response = get_response(request)
               ^^^^^^^^^^^^^^^^^^^^^
  File "/workspace/.pip-modules/lib/python3.12/site-packages/django/core/handlers/base.py", line 197, in _get_response
    response = wrapped_callback(request, *callback_args, **callback_kwargs)
               ^^^^^^^^^^^^^^^^^^^^^^^^^^^^^^^^^^^^^^^^^^^^^^^^^^^^^^^^^^^^
  File "/workspace/django-renterprise/customers/views.py", line 355, in invoice_create
    logger.warning(request.amount_paid)
                   ^^^^^^^^^^^^^^^^^^^
AttributeError: 'WSGIRequest' object has no attribute 'amount_paid'
django.request WARNING 2024-06-13 01:47:31,750 log 7944 139889735611968 Not Found: /favicon.ico
django.request WARNING 2024-06-13 01:47:31,811 log 7944 139889727219264 Not Found: /customers/8e05b134-0b51-46e4-ac9d-2e725f265a9b/orders/8/invoice_create/styles.css.map
